#VRML_SIM R2025a utf8

EXTERNPROTO "https://raw.githubusercontent.com/cyberbotics/webots/R2025a/projects/objects/backgrounds/protos/TexturedBackground.proto"
EXTERNPROTO "https://raw.githubusercontent.com/cyberbotics/webots/R2025a/projects/objects/backgrounds/protos/TexturedBackgroundLight.proto"
EXTERNPROTO "https://raw.githubusercontent.com/cyberbotics/webots/R2025a/projects/objects/floors/protos/RectangleArena.proto"

WorldInfo {
}
Viewpoint {
  orientation -0.46088383789558846 0.3516988979597117 0.814796890728332 2.029054106434855
  position 0.5592268273347238 -3.7103564065324526 5.463454650761927
}
TexturedBackground {
}
TexturedBackgroundLight {
}
RectangleArena {
  translation 1.59215e-07 0 0.03
  rotation 0 1 0 5.30716e-06
  floorSize 4 4
}
DEF Obs1 Solid {
  translation -0.968802 -0.0605635 0.142502
  rotation -0.0025754902978973823 0.002671230308971273 0.9999931156654838 -1.5881053071795863
  children [
    Shape {
      appearance PBRAppearance {
      }
      geometry Box {
        size 1 0.05 0.5
      }
    }
  ]
}
Robot {
  translation -1.402649126726977 -1.7193541651201159 0.06990241584841671
  rotation -0.0017971376886949247 -0.0015630124432457154 -0.9999971636400927 3.1405140845185193
  children [
    Compass {
    }
    DEF gps GPS {
      translation -0.05 -0.02 0.03
      children [
        Shape {
          appearance PBRAppearance {
          }
          geometry Cylinder {
            height 0.02
            radius 0.02
          }
        }
      ]
      boundingObject Shape {
        appearance PBRAppearance {
        }
        geometry Cylinder {
          height 0.02
          radius 0.02
        }
      }
      physics Physics {
      }
    }
    DEF lidar Lidar {
      translation 0.07 -0.02 0.04
      children [
        Shape {
          appearance PBRAppearance {
          }
          geometry Cylinder {
            height 0.025
            radius 0.025
          }
        }
      ]
      boundingObject Shape {
        appearance PBRAppearance {
        }
        geometry Cylinder {
          height 0.025
          radius 0.025
        }
      }
      physics Physics {
      }
      horizontalResolution 128
      fieldOfView 3.14
      verticalFieldOfView 0.1
      numberOfLayers 1
    }
    DEF BODY Shape {
      appearance PBRAppearance {
        baseColor 0.917647 0.145098 0.145098
        roughness 1
        metalness 0
      }
      geometry Box {
        size 0.2 0.1 0.05
      }
    }
    DEF WHEEL1 HingeJoint {
      jointParameters HingeJointParameters {
        position 7695.1903044617375
        axis 0 1 0
        anchor 0.05 0.06 0
      }
      device [
        RotationalMotor {
          name "wheel1"
        }
      ]
      endPoint Solid {
        translation 0.05050783544338393 0.06043224674532349 -0.0007526338993644805
        rotation -0.5285412650286181 0.5962827198444476 -0.6042276468160456 4.09071197361437
        children [
          DEF WHEEL Shape {
            appearance PBRAppearance {
              baseColor 0.305882 0.898039 0.25098
              roughness 1
              metalness 0
            }
            geometry Cylinder {
              height 0.02
              radius 0.04
              subdivision 24
            }
          }
        ]
        boundingObject USE WHEEL
        physics Physics {
        }
      }
    }
    DEF WHEEL2 HingeJoint {
      jointParameters HingeJointParameters {
        position 5512.975802812592
        axis 0 1 0
        anchor 0.05 -0.06 0
      }
      device [
        RotationalMotor {
          name "wheel2"
        }
      ]
      endPoint Solid {
        translation 0.05000204348086025 -0.06000008469764562 -8.691734227175798e-07
        rotation 0.18461381896641535 0.6949511339763144 -0.6949537101359128 2.7764773292962737
        children [
          USE WHEEL
        ]
        name "solid(1)"
        boundingObject USE WHEEL
        physics Physics {
        }
      }
    }
    DEF WHEEL3 HingeJoint {
      jointParameters HingeJointParameters {
        position 7695.1901115433675
        axis 0 1 0
        anchor -0.05 0.06 0
      }
      device [
        RotationalMotor {
          name "wheel3"
        }
      ]
      endPoint Solid {
        translation -0.05000107130123011 0.060000084994313085 -4.517926920903338e-06
        rotation 0.5230987082111807 -0.6026462601611274 0.6026485099804036 2.177684936366459
        children [
          USE WHEEL
        ]
        name "solid(2)"
        boundingObject USE WHEEL
        physics Physics {
        }
      }
    }
    DEF WHEEL4 HingeJoint {
      jointParameters HingeJointParameters {
        position 5512.9751754182125
        axis 0 1 0
        anchor -0.05 -0.06 0
      }
      device [
        RotationalMotor {
          name "wheel4"
        }
      ]
      endPoint Solid {
        translation -0.049997973300932745 -0.05999991499841628 -5.597460698849198e-07
        rotation 0.18483925753500585 0.694921168964124 -0.6949237496297296 2.7760413287595234
        children [
          USE WHEEL
        ]
        name "solid(3)"
        boundingObject USE WHEEL
        physics Physics {
        }
      }
    }
    DEF DS_RIGHT DistanceSensor {
      translation 0.1 -0.03 0
      rotation 0 0 1 -0.3
      children [
        Shape {
          appearance PBRAppearance {
            baseColor 0.184314 0.596078 0.847059
            roughness 1
            metalness 0
          }
          geometry Box {
            size 0.01 0.01 0.01
          }
        }
      ]
      name "ds_right"
    }
    DEF DS_LEFT DistanceSensor {
      translation 0.1 0.03 0
      rotation 0 0 1 0.3
      children [
        Shape {
          appearance PBRAppearance {
            baseColor 0.184314 0.596078 0.847059
            roughness 1
            metalness 0
          }
          geometry Box {
            size 0.01 0.01 0.01
          }
        }
      ]
      name "ds_left"
    }
  ]
  boundingObject USE BODY
  physics Physics {
    density -1
    mass 1
  }
  controller "controlador"
  window "<none>"
}
Solid {
  translation 0.118501 -1.97991 2.22045e-16
  children [
    Shape {
      appearance PBRAppearance {
      }
      geometry Box {
        size 3.8 0.06 0.6
      }
    }
  ]
  name "solid(1)"
}
Solid {
  translation -0.492309 -1.45343 2.22045e-16
  children [
    Shape {
      appearance PBRAppearance {
      }
      geometry Box {
        size 3.8 0.06 0.6
      }
    }
  ]
  name "solid(3)"
}
Solid {
  translation 1.9968 -0.095336 1.11022e-15
  rotation 0 0 -1 1.57734
  children [
    Shape {
      appearance PBRAppearance {
      }
      geometry Box {
        size 3.8 0.06 0.6
      }
    }
  ]
  name "solid(4)"
}
Solid {
  translation 1.39453 0.419462 3.77476e-15
  rotation 0 0 -1 1.57734
  children [
    Shape {
      appearance PBRAppearance {
      }
      geometry Box {
        size 3.8 0.06 0.6
      }
    }
  ]
  name "solid(5)"
}
Solid {
  translation 0 1.15 0.09
  children [
    Shape {
      appearance PBRAppearance {
      }
      geometry Box {
        size 2 0.05 0.6
      }
    }
  ]
  name "solid(2)"
}
