#VRML_SIM R2025a utf8

EXTERNPROTO "https://raw.githubusercontent.com/cyberbotics/webots/R2025a/projects/objects/backgrounds/protos/TexturedBackground.proto"
EXTERNPROTO "https://raw.githubusercontent.com/cyberbotics/webots/R2025a/projects/objects/backgrounds/protos/TexturedBackgroundLight.proto"
EXTERNPROTO "https://raw.githubusercontent.com/cyberbotics/webots/R2025a/projects/objects/floors/protos/RectangleArena.proto"

WorldInfo {
}
Viewpoint {
  orientation 0.3849151362438018 0.03687435682775987 -0.9222150615225032 2.965348929787461
  position 6.361210962163885 -0.5950791579303865 4.963302748574215
}
TexturedBackground {
}
TexturedBackgroundLight {
}
RectangleArena {
  translation 1.59215e-07 0 0.03
  rotation 0 1 0 5.30716e-06
  floorSize 4 4
}
Solid {
  translation -0.892618 1.99971 0.09
  rotation 0 0 1 3.13699
  children [
    Shape {
      appearance PBRAppearance {
      }
      geometry Box {
        size 2 0.05 0.6
      }
    }
  ]
  name "solid(13)"
}
Solid {
  translation -0.982629 2.00335 0.09
  rotation 0 0 1 3.13699
  children [
    Shape {
      appearance PBRAppearance {
      }
      geometry Box {
        size 2 0.05 0.6
      }
    }
  ]
  name "solid(15)"
}
Solid {
  translation 1.01288 1.98967 0.09
  rotation 0 0 1 3.13699
  children [
    Shape {
      appearance PBRAppearance {
      }
      geometry Box {
        size 2 0.05 0.6
      }
    }
  ]
  name "solid(10)"
}
Solid {
  translation -0.241619 1.21022 0.09
  rotation 0 0 1 3.13699
  children [
    Shape {
      appearance PBRAppearance {
      }
      geometry Box {
        size 2 0.05 0.6
      }
    }
  ]
  name "solid(11)"
}
Solid {
  translation -1.98792 1.02674 0.09
  rotation 0 0 1 1.56389
  children [
    Shape {
      appearance PBRAppearance {
      }
      geometry Box {
        size 2 0.05 0.6
      }
    }
  ]
  name "solid(12)"
}
Solid {
  translation -1.99998 -0.0753114 0.09
  rotation 0 0 1 1.56389
  children [
    Shape {
      appearance PBRAppearance {
      }
      geometry Box {
        size 2 0.05 0.6
      }
    }
  ]
  name "solid(16)"
}
Solid {
  translation -1.25179 0.240747 0.09
  rotation 0 0 1 1.56389
  children [
    Shape {
      appearance PBRAppearance {
      }
      geometry Box {
        size 2 0.05 0.6
      }
    }
  ]
  name "solid(14)"
}
DEF Obs1 Solid {
  translation 1.24472 0.726885 0.142502
  rotation -0.002671400183432755 -0.00259350017808372 -0.9999930686649214 1.5812
  children [
    Shape {
      appearance PBRAppearance {
      }
      geometry Box {
        size 1 0.05 0.5
      }
    }
  ]
  name "solid(9)"
}
DEF Obs1 Solid {
  translation 1.23576 -0.765675 0.142502
  rotation -0.0026716300132759957 -0.002617710013008054 -0.9999930049692147 1.572
  children [
    Shape {
      appearance PBRAppearance {
      }
      geometry Box {
        size 1 0.05 0.5
      }
    }
  ]
  name "solid(5)"
}
DEF Obs1 Solid {
  translation 1.23386 0.172747 0.142502
  rotation -0.002671400183432755 -0.00259350017808372 -0.9999930686649214 1.5812
  children [
    Shape {
      appearance PBRAppearance {
      }
      geometry Box {
        size 1 0.05 0.5
      }
    }
  ]
  name "solid(7)"
}
DEF Obs1 Solid {
  translation 1.99175 1.53014 0.142502
  rotation -0.0026718598400413715 -0.0026421298418212442 -0.9999929401325263 1.5628
  children [
    Shape {
      appearance PBRAppearance {
      }
      geometry Box {
        size 1 0.05 0.5
      }
    }
  ]
  name "solid(8)"
}
DEF Obs1 Solid {
  translation -2.0167 -1.42308 0.142502
  rotation 0.0026237899708097855 -0.0026716899702768876 -0.9999929888748679 1.56971
  children [
    Shape {
      appearance PBRAppearance {
      }
      geometry Box {
        size 1 0.05 0.5
      }
    }
  ]
}
DEF Obs1 Solid {
  translation 1.51929 -2.01243 0.142502
  rotation -0.00885806135487618 -0.9792841497854571 0.2022970309421461 0.00540457
  children [
    Shape {
      appearance PBRAppearance {
      }
      geometry Box {
        size 1 0.05 0.5
      }
    }
  ]
  name "solid(6)"
}
Robot {
  translation -1.492479264799465 -1.7388066759342857 0.06994707838001596
  rotation 0.23517365939497847 -0.2707971538753155 0.9334678630674992 0.016400953382631384
  children [
    Compass {
    }
    DEF gps GPS {
      translation -0.05 -0.02 0.03
      children [
        Shape {
          appearance PBRAppearance {
          }
          geometry Cylinder {
            height 0.02
            radius 0.02
          }
        }
      ]
      boundingObject Shape {
        appearance PBRAppearance {
        }
        geometry Cylinder {
          height 0.02
          radius 0.02
        }
      }
      physics Physics {
      }
    }
    DEF lidar Lidar {
      translation 0.07 -0.02 0.04
      children [
        Shape {
          appearance PBRAppearance {
          }
          geometry Cylinder {
            height 0.025
            radius 0.025
          }
        }
      ]
      boundingObject Shape {
        appearance PBRAppearance {
        }
        geometry Cylinder {
          height 0.025
          radius 0.025
        }
      }
      physics Physics {
      }
      horizontalResolution 128
      fieldOfView 3.14
      verticalFieldOfView 0.1
      numberOfLayers 1
    }
    DEF BODY Shape {
      appearance PBRAppearance {
        baseColor 0.917647 0.145098 0.145098
        roughness 1
        metalness 0
      }
      geometry Box {
        size 0.2 0.1 0.05
      }
    }
    DEF WHEEL1 HingeJoint {
      jointParameters HingeJointParameters {
        position 7664.381566218011
        axis 0 1 0
        anchor 0.05 0.06 0
      }
      device [
        RotationalMotor {
          name "wheel1"
        }
      ]
      endPoint Solid {
        translation 0.04998763941679812 0.06043224674532349 -0.0009078556272956897
        rotation 0.75783287846895 -0.45960551523328375 0.46308973069872034 1.8680294761023983
        children [
          DEF WHEEL Shape {
            appearance PBRAppearance {
              baseColor 0.305882 0.898039 0.25098
              roughness 1
              metalness 0
            }
            geometry Cylinder {
              height 0.02
              radius 0.04
              subdivision 24
            }
          }
        ]
        boundingObject USE WHEEL
        physics Physics {
        }
        linearVelocity 0.0787794586544279 0.02091615622091337 -6.488926266117433e-05
        angularVelocity -0.0037404296652856963 -4.001035545441672 0.6368078125913603
      }
    }
    DEF WHEEL2 HingeJoint {
      jointParameters HingeJointParameters {
        position 5530.965982236938
        axis 0 1 0
        anchor 0.05 -0.06 0
      }
      device [
        RotationalMotor {
          name "wheel2"
        }
      ]
      endPoint Solid {
        translation 0.05000199255170834 -0.06000008469764562 9.803132940917854e-07
        rotation -0.5035388696474135 -0.6109197363294473 0.6109219938071995 4.074539041098886
        children [
          USE WHEEL
        ]
        name "solid(1)"
        boundingObject USE WHEEL
        physics Physics {
        }
        linearVelocity 0.15371531213231412 0.020879239532752714 7.548550381065811e-05
        angularVelocity 0.005678666482814289 3.998973528477726 0.6673967666200776
      }
    }
    DEF WHEEL3 HingeJoint {
      jointParameters HingeJointParameters {
        position 7664.381364644829
        axis 0 1 0
        anchor -0.05 0.06 0
      }
      device [
        RotationalMotor {
          name "wheel3"
        }
      ]
      endPoint Solid {
        translation -0.05000345753625762 0.060000084994313085 -3.0991600499967335e-06
        rotation -0.7538271034191162 0.46461977604568455 -0.4646215253924456 4.433481042702365
        children [
          USE WHEEL
        ]
        name "solid(2)"
        boundingObject USE WHEEL
        physics Physics {
        }
        linearVelocity 0.07535672465904095 -0.044125453791772205 7.950129608408731e-05
        angularVelocity -0.0037376079131248886 -4.001038073019669 0.6368079300214977
      }
    }
    DEF WHEEL4 HingeJoint {
      jointParameters HingeJointParameters {
        position 5530.965347032276
        axis 0 1 0
        anchor -0.05 -0.06 0
      }
      device [
        RotationalMotor {
          name "wheel4"
        }
      ]
      endPoint Solid {
        translation -0.0499982527857235 -0.05999991499841628 1.169643981691272e-06
        rotation -0.5037821002088533 -0.6108194625462806 0.6108217249605894 4.074927067700416
        children [
          USE WHEEL
        ]
        name "solid(3)"
        boundingObject USE WHEEL
        physics Physics {
        }
        linearVelocity 0.15363360725016506 -0.04422980321285867 -2.5583865697169917e-05
        angularVelocity 0.005681428225287491 3.9989712128394905 0.6673967519041354
      }
    }
    DEF DS_RIGHT DistanceSensor {
      translation 0.1 -0.03 0
      rotation 0 0 1 -0.3
      children [
        Shape {
          appearance PBRAppearance {
            baseColor 0.184314 0.596078 0.847059
            roughness 1
            metalness 0
          }
          geometry Box {
            size 0.01 0.01 0.01
          }
        }
      ]
      name "ds_right"
    }
    DEF DS_LEFT DistanceSensor {
      translation 0.1 0.03 0
      rotation 0 0 1 0.3
      children [
        Shape {
          appearance PBRAppearance {
            baseColor 0.184314 0.596078 0.847059
            roughness 1
            metalness 0
          }
          geometry Box {
            size 0.01 0.01 0.01
          }
        }
      ]
      name "ds_left"
    }
  ]
  boundingObject USE BODY
  physics Physics {
    density -1
    mass 1
  }
  controller "controlador"
  window "<none>"
  linearVelocity 0.1154346185149939 -0.010311663377167768 9.066793764975713e-05
  angularVelocity 0.0009640701318571442 -0.0010311466582568953 0.6518192134651467
}
Solid {
  translation -0.101041 -2.00785 2.22045e-16
  children [
    Shape {
      appearance PBRAppearance {
      }
      geometry Box {
        size 3.8 0.06 0.6
      }
    }
  ]
  name "solid(1)"
}
Solid {
  translation -0.627914 -1.23342 -6.66133e-16
  children [
    Shape {
      appearance PBRAppearance {
      }
      geometry Box {
        size 3.8 0.06 0.6
      }
    }
  ]
  name "solid(3)"
}
Solid {
  translation 1.9968 -0.095336 1.11022e-15
  rotation 0 0 -1 1.55894
  children [
    Shape {
      appearance PBRAppearance {
      }
      geometry Box {
        size 3.8 0.06 0.6
      }
    }
  ]
  name "solid(4)"
}
Solid {
  translation 0.24367 1.19773 0.09
  children [
    Shape {
      appearance PBRAppearance {
      }
      geometry Box {
        size 2 0.05 0.6
      }
    }
  ]
  name "solid(2)"
}
